Workbook

Sheet Income
A1: INCOME STATEMENT - REVENUE SECTION | B1: Document Number | C1: Description | D1: Customer | E1: Category | F1: Payment Method | G1: Status | H1: Amount | I1: Notes
A75: 46025 | C75: Share 0001 | D75: Deposit | E75: Transfer | F75: Completed | G75: 60

Sheet Expenses
A1: Date | B1: Document Number | C1: Description | D1: Supplier | E1: Category | F1: Type | G1: Payment Method | H1: Status | I1: Amount | J1: Notes
F37: =IF(E37="","",IFERROR(_xlfn.XLOOKUP(E37,Settings!$F$2:$F$36,Settings!$E$2:$E$36,""),""))
F38: =IF(E38="","",IFERROR(_xlfn.XLOOKUP(E38,Settings!$F$2:$F$36,Settings!$E$2:$E$36,""),""))
F39: =IF(E39="","",IFERROR(_xlfn.XLOOKUP(E39,Settings!$F$2:$F$36,Settings!$E$2:$E$36,""),""))
F40: =IF(E40="","",IFERROR(_xlfn.XLOOKUP(E40,Settings!$F$2:$F$36,Settings!$E$2:$E$36,""),""))
F41: =IF(E41="","",IFERROR(_xlfn.XLOOKUP(E41,Settings!$F$2:$F$36,Settings!$E$2:$E$36,""),""))
F42: =IF(E42="","",IFERROR(_xlfn.XLOOKUP(E42,Settings!$F$2:$F$36,Settings!$E$2:$E$36,""),""))
F43: =IF(E43="","",IFERROR(_xlfn.XLOOKUP(E43,Settings!$F$2:$F$36,Settings!$E$2:$E$36,""),""))
F44: =IF(E44="","",IFERROR(_xlfn.XLOOKUP(E44,Settings!$F$2:$F$36,Settings!$E$2:$E$36,""),""))
F45: =IF(E45="","",IFERROR(_xlfn.XLOOKUP(E45,Settings!$F$2:$F$36,Settings!$E$2:$E$36,""),""))
F46: =IF(E46="","",IFERROR(_xlfn.XLOOKUP(E46,Settings!$F$2:$F$36,Settings!$E$2:$E$36,""),""))
F47: =IF(E47="","",IFERROR(_xlfn.XLOOKUP(E47,Settings!$F$2:$F$36,Settings!$E$2:$E$36,""),""))
F48: =IF(E48="","",IFERROR(_xlfn.XLOOKUP(E48,Settings!$F$2:$F$36,Settings!$E$2:$E$36,""),""))
... F500: =IF(E500="","",IFERROR(_xlfn.XLOOKUP(E500,Settings!$F$2:$F$36,Settings!$E$2:$E$36,""),""))
F501: =IF(E501="","",IFERROR(_xlfn.XLOOKUP(E501,Settings!$F$2:$F$38,Settings!$E$2:$E$38,""),""))
F502: =IF(E502="","",IFERROR(_xlfn.XLOOKUP(E502,Settings!$F$2:$F$38,Settings!$E$2:$E$38,""),""))
F503: =IF(E503="","",IFERROR(_xlfn.XLOOKUP(E503,Settings!$F$2:$F$38,Settings!$E$2:$E$38,""),""))
F504: =IF(E504="","",IFERROR(_xlfn.XLOOKUP(E504,Settings!$F$2:$F$38,Settings!$E$2:$E$38,""),""))
F505: =IF(E505="","",IFERROR(_xlfn.XLOOKUP(E505,Settings!$F$2:$F$38,Settings!$E$2:$E$38,""),""))
F506: =IF(E506="","",IFERROR(_xlfn.XLOOKUP(E506,Settings!$F$2:$F$38,Settings!$E$2:$E$38,""),""))
F507: =IF(E507="","",IFERROR(_xlfn.XLOOKUP(E507,Settings!$F$2:$F$38,Settings!$E$2:$E$38,""),""))
F508: =IF(E508="","",IFERROR(_xlfn.XLOOKUP(E508,Settings!$F$2:$F$38,Settings!$E$2:$E$38,""),""))
F509: =IF(E509="","",IFERROR(_xlfn.XLOOKUP(E509,Settings!$F$2:$F$38,Settings!$E$2:$E$38,""),""))
F510: =IF(E510="","",IFERROR(_xlfn.XLOOKUP(E510,Settings!$F$2:$F$38,Settings!$E$2:$E$38,""),""))
F511: =IF(E511="","",IFERROR(_xlfn.XLOOKUP(E511,Settings!$F$2:$F$38,Settings!$E$2:$E$38,""),""))
F512: =IF(E512="","",IFERROR(_xlfn.XLOOKUP(E512,Settings!$F$2:$F$38,Settings!$E$2:$E$38,""),""))
... F983: =IF(E983="","",IFERROR(_xlfn.XLOOKUP(E983,Settings!$F$2:$F$38,Settings!$E$2:$E$38,""),""))

Sheet P&L
A1: PROFIT & LOSS STATEMENT
A2: Fiscal Year 2026
A4: Account | B4: Jan | C4: Feb | D4: Mar | E4: Apr | F4: May | G4: Jun | H4: Jul | I4: Aug | J4: Sep | K4: Oct | L4: Nov | M4: Dec | N4: YTD Total
A5: REVENUE / INGRESOS
A6: Gross receipts or sales | B6: =SUMIFS(TablaIngresos[Amount],TablaIngresos[Category],$A6,TablaIngresos[INCOME STATEMENT - REVENUE SECTION],">="&DATE(2026,1,1),TablaIngresos[INCOME STATEMENT - REVENUE SECTION],"<"&DATE(2026,2,1)) | C6: =SUMIFS(TablaIngresos[Amount],TablaIngresos[Category],$A6,TablaIngresos[INCOME STATEMENT - REVENUE SECTION],">="&DATE(2026,2,1),TablaIngresos[INCOME STATEMENT - REVENUE SECTION],"<"&DATE(2026,3,1)) | D6: =SUMIFS(TablaIngresos[Amount],TablaIngresos[Category],$A6,TablaIngresos[INCOME STATEMENT - REVENUE SECTION],">="&DATE(2026,3,1),TablaIngresos[INCOME STATEMENT - REVENUE SECTION],"<"&DATE(2026,4,1)) | E6: =SUMIFS(TablaIngresos[Amount],TablaIngresos[Category],$A6,TablaIngresos[INCOME STATEMENT - REVENUE SECTION],">="&DATE(2026,4,1),TablaIngresos[INCOME STATEMENT - REVENUE SECTION],"<"&DATE(2026,5,1)) | F6: =SUMIFS(TablaIngresos[Amount],TablaIngresos[Category],$A6,TablaIngresos[INCOME STATEMENT - REVENUE SECTION],">="&DATE(2026,5,1),TablaIngresos[INCOME STATEMENT - REVENUE SECTION],"<"&DATE(2026,6,1)) | G6: =SUMIFS(TablaIngresos[Amount],TablaIngresos[Category],$A6,TablaIngresos[INCOME STATEMENT - REVENUE SECTION],">="&DATE(2026,6,1),TablaIngresos[INCOME STATEMENT - REVENUE SECTION],"<"&DATE(2026,7,1)) | H6: =SUMIFS(TablaIngresos[Amount],TablaIngresos[Category],$A6,TablaIngresos[INCOME STATEMENT - REVENUE SECTION],">="&DATE(2026,7,1),TablaIngresos[INCOME STATEMENT - REVENUE SECTION],"<"&DATE(2026,8,1)) | I6: =SUMIFS(TablaIngresos[Amount],TablaIngresos[Category],$A6,TablaIngresos[INCOME STATEMENT - REVENUE SECTION],">="&DATE(2026,8,1),TablaIngresos[INCOME STATEMENT - REVENUE SECTION],"<"&DATE(2026,9,1)) | J6: =SUMIFS(TablaIngresos[Amount],TablaIngresos[Category],$A6,TablaIngresos[INCOME STATEMENT - REVENUE SECTION],">="&DATE(2026,9,1),TablaIngresos[INCOME STATEMENT - REVENUE SECTION],"<"&DATE(2026,10,1)) | K6: =SUMIFS(TablaIngresos[Amount],TablaIngresos[Category],$A6,TablaIngresos[INCOME STATEMENT - REVENUE SECTION],">="&DATE(2026,10,1),TablaIngresos[INCOME STATEMENT - REVENUE SECTION],"<"&DATE(2026,11,1)) | L6: =SUMIFS(TablaIngresos[Amount],TablaIngresos[Category],$A6,TablaIngresos[INCOME STATEMENT - REVENUE SECTION],">="&DATE(2026,11,1),TablaIngresos[INCOME STATEMENT - REVENUE SECTION],"<"&DATE(2026,12,1)) | M6: =SUMIFS(TablaIngresos[Amount],TablaIngresos[Category],$A6,TablaIngresos[INCOME STATEMENT - REVENUE SECTION],">="&DATE(2026,12,1),TablaIngresos[INCOME STATEMENT - REVENUE SECTION],"<"&DATE(2027,1,1)) | N6: =SUM(B6:M6)
A7: Other income | B7: =SUMIFS(TablaIngresos[Amount],TablaIngresos[Category],$A7,TablaIngresos[INCOME STATEMENT - REVENUE SECTION],">="&DATE(2026,1,1),TablaIngresos[INCOME STATEMENT - REVENUE SECTION],"<"&DATE(2026,2,1)) | C7: =SUMIFS(TablaIngresos[Amount],TablaIngresos[Category],$A7,TablaIngresos[INCOME STATEMENT - REVENUE SECTION],">="&DATE(2026,2,1),TablaIngresos[INCOME STATEMENT - REVENUE SECTION],"<"&DATE(2026,3,1)) | D7: =SUMIFS(TablaIngresos[Amount],TablaIngresos[Category],$A7,TablaIngresos[INCOME STATEMENT - REVENUE SECTION],">="&DATE(2026,3,1),TablaIngresos[INCOME STATEMENT - REVENUE SECTION],"<"&DATE(2026,4,1)) | E7: =SUMIFS(TablaIngresos[Amount],TablaIngresos[Category],$A7,TablaIngresos[INCOME STATEMENT - REVENUE SECTION],">="&DATE(2026,4,1),TablaIngresos[INCOME STATEMENT - REVENUE SECTION],"<"&DATE(2026,5,1)) | F7: =SUMIFS(TablaIngresos[Amount],TablaIngresos[Category],$A7,TablaIngresos[INCOME STATEMENT - REVENUE SECTION],">="&DATE(2026,5,1),TablaIngresos[INCOME STATEMENT - REVENUE SECTION],"<"&DATE(2026,6,1)) | G7: =SUMIFS(TablaIngresos[Amount],TablaIngresos[Category],$A7,TablaIngresos[INCOME STATEMENT - REVENUE SECTION],">="&DATE(2026,6,1),TablaIngresos[INCOME STATEMENT - REVENUE SECTION],"<"&DATE(2026,7,1)) | H7: =SUMIFS(TablaIngresos[Amount],TablaIngresos[Category],$A7,TablaIngresos[INCOME STATEMENT - REVENUE SECTION],">="&DATE(2026,7,1),TablaIngresos[INCOME STATEMENT - REVENUE SECTION],"<"&DATE(2026,8,1)) | I7: =SUMIFS(TablaIngresos[Amount],TablaIngresos[Category],$A7,TablaIngresos[INCOME STATEMENT - REVENUE SECTION],">="&DATE(2026,8,1),TablaIngresos[INCOME STATEMENT - REVENUE SECTION],"<"&DATE(2026,9,1)) | J7: =SUMIFS(TablaIngresos[Amount],TablaIngresos[Category],$A7,TablaIngresos[INCOME STATEMENT - REVENUE SECTION],">="&DATE(2026,9,1),TablaIngresos[INCOME STATEMENT - REVENUE SECTION],"<"&DATE(2026,10,1)) | K7: =SUMIFS(TablaIngresos[Amount],TablaIngresos[Category],$A7,TablaIngresos[INCOME STATEMENT - REVENUE SECTION],">="&DATE(2026,10,1),TablaIngresos[INCOME STATEMENT - REVENUE SECTION],"<"&DATE(2026,11,1)) | L7: =SUMIFS(TablaIngresos[Amount],TablaIngresos[Category],$A7,TablaIngresos[INCOME STATEMENT - REVENUE SECTION],">="&DATE(2026,11,1),TablaIngresos[INCOME STATEMENT - REVENUE SECTION],"<"&DATE(2026,12,1)) | M7: =SUMIFS(TablaIngresos[Amount],TablaIngresos[Category],$A7,TablaIngresos[INCOME STATEMENT - REVENUE SECTION],">="&DATE(2026,12,1),TablaIngresos[INCOME STATEMENT - REVENUE SECTION],"<"&DATE(2027,1,1)) | N7: =SUM(B7:M7)
A8: Interest income | B8: =SUMIFS(TablaIngresos[Amount],TablaIngresos[Category],$A8,TablaIngresos[INCOME STATEMENT - REVENUE SECTION],">="&DATE(2026,1,1),TablaIngresos[INCOME STATEMENT - REVENUE SECTION],"<"&DATE(2026,2,1)) | C8: =SUMIFS(TablaIngresos[Amount],TablaIngresos[Category],$A8,TablaIngresos[INCOME STATEMENT - REVENUE SECTION],">="&DATE(2026,2,1),TablaIngresos[INCOME STATEMENT - REVENUE SECTION],"<"&DATE(2026,3,1)) | D8: =SUMIFS(TablaIngresos[Amount],TablaIngresos[Category],$A8,TablaIngresos[INCOME STATEMENT - REVENUE SECTION],">="&DATE(2026,3,1),TablaIngresos[INCOME STATEMENT - REVENUE SECTION],"<"&DATE(2026,4,1)) | E8: =SUMIFS(TablaIngresos[Amount],TablaIngresos[Category],$A8,TablaIngresos[INCOME STATEMENT - REVENUE SECTION],">="&DATE(2026,4,1),TablaIngresos[INCOME STATEMENT - REVENUE SECTION],"<"&DATE(2026,5,1)) | F8: =SUMIFS(TablaIngresos[Amount],TablaIngresos[Category],$A8,TablaIngresos[INCOME STATEMENT - REVENUE SECTION],">="&DATE(2026,5,1),TablaIngresos[INCOME STATEMENT - REVENUE SECTION],"<"&DATE(2026,6,1)) | G8: =SUMIFS(TablaIngresos[Amount],TablaIngresos[Category],$A8,TablaIngresos[INCOME STATEMENT - REVENUE SECTION],">="&DATE(2026,6,1),TablaIngresos[INCOME STATEMENT - REVENUE SECTION],"<"&DATE(2026,7,1)) | H8: =SUMIFS(TablaIngresos[Amount],TablaIngresos[Category],$A8,TablaIngresos[INCOME STATEMENT - REVENUE SECTION],">="&DATE(2026,7,1),TablaIngresos[INCOME STATEMENT - REVENUE SECTION],"<"&DATE(2026,8,1)) | I8: =SUMIFS(TablaIngresos[Amount],TablaIngresos[Category],$A8,TablaIngresos[INCOME STATEMENT - REVENUE SECTION],">="&DATE(2026,8,1),TablaIngresos[INCOME STATEMENT - REVENUE SECTION],"<"&DATE(2026,9,1)) | J8: =SUMIFS(TablaIngresos[Amount],TablaIngresos[Category],$A8,TablaIngresos[INCOME STATEMENT - REVENUE SECTION],">="&DATE(2026,9,1),TablaIngresos[INCOME STATEMENT - REVENUE SECTION],"<"&DATE(2026,10,1)) | K8: =SUMIFS(TablaIngresos[Amount],TablaIngresos[Category],$A8,TablaIngresos[INCOME STATEMENT - REVENUE SECTION],">="&DATE(2026,10,1),TablaIngresos[INCOME STATEMENT - REVENUE SECTION],"<"&DATE(2026,11,1)) | L8: =SUMIFS(TablaIngresos[Amount],TablaIngresos[Category],$A8,TablaIngresos[INCOME STATEMENT - REVENUE SECTION],">="&DATE(2026,11,1),TablaIngresos[INCOME STATEMENT - REVENUE SECTION],"<"&DATE(2026,12,1)) | M8: =SUMIFS(TablaIngresos[Amount],TablaIngresos[Category],$A8,TablaIngresos[INCOME STATEMENT - REVENUE SECTION],">="&DATE(2026,12,1),TablaIngresos[INCOME STATEMENT - REVENUE SECTION],"<"&DATE(2027,1,1)) | N8: =SUM(B8:M8)
A9: Dividend income | B9: =SUMIFS(TablaIngresos[Amount],TablaIngresos[Category],$A9,TablaIngresos[INCOME STATEMENT - REVENUE SECTION],">="&DATE(2026,1,1),TablaIngresos[INCOME STATEMENT - REVENUE SECTION],"<"&DATE(2026,2,1)) | C9: =SUMIFS(TablaIngresos[Amount],TablaIngresos[Category],$A9,TablaIngresos[INCOME STATEMENT - REVENUE SECTION],">="&DATE(2026,2,1),TablaIngresos[INCOME STATEMENT - REVENUE SECTION],"<"&DATE(2026,3,1)) | D9: =SUMIFS(TablaIngresos[Amount],TablaIngresos[Category],$A9,TablaIngresos[INCOME STATEMENT - REVENUE SECTION],">="&DATE(2026,3,1),TablaIngresos[INCOME STATEMENT - REVENUE SECTION],"<"&DATE(2026,4,1)) | E9: =SUMIFS(TablaIngresos[Amount],TablaIngresos[Category],$A9,TablaIngresos[INCOME STATEMENT - REVENUE SECTION],">="&DATE(2026,4,1),TablaIngresos[INCOME STATEMENT - REVENUE SECTION],"<"&DATE(2026,5,1)) | F9: =SUMIFS(TablaIngresos[Amount],TablaIngresos[Category],$A9,TablaIngresos[INCOME STATEMENT - REVENUE SECTION],">="&DATE(2026,5,1),TablaIngresos[INCOME STATEMENT - REVENUE SECTION],"<"&DATE(2026,6,1)) | G9: =SUMIFS(TablaIngresos[Amount],TablaIngresos[Category],$A9,TablaIngresos[INCOME STATEMENT - REVENUE SECTION],">="&DATE(2026,6,1),TablaIngresos[INCOME STATEMENT - REVENUE SECTION],"<"&DATE(2026,7,1)) | H9: =SUMIFS(TablaIngresos[Amount],TablaIngresos[Category],$A9,TablaIngresos[INCOME STATEMENT - REVENUE SECTION],">="&DATE(2026,7,1),TablaIngresos[INCOME STATEMENT - REVENUE SECTION],"<"&DATE(2026,8,1)) | I9: =SUMIFS(TablaIngresos[Amount],TablaIngresos[Category],$A9,TablaIngresos[INCOME STATEMENT - REVENUE SECTION],">="&DATE(2026,8,1),TablaIngresos[INCOME STATEMENT - REVENUE SECTION],"<"&DATE(2026,9,1)) | J9: =SUMIFS(TablaIngresos[Amount],TablaIngresos[Category],$A9,TablaIngresos[INCOME STATEMENT - REVENUE SECTION],">="&DATE(2026,9,1),TablaIngresos[INCOME STATEMENT - REVENUE SECTION],"<"&DATE(2026,10,1)) | K9: =SUMIFS(TablaIngresos[Amount],TablaIngresos[Category],$A9,TablaIngresos[INCOME STATEMENT - REVENUE SECTION],">="&DATE(2026,10,1),TablaIngresos[INCOME STATEMENT - REVENUE SECTION],"<"&DATE(2026,11,1)) | L9: =SUMIFS(TablaIngresos[Amount],TablaIngresos[Category],$A9,TablaIngresos[INCOME STATEMENT - REVENUE SECTION],">="&DATE(2026,11,1),TablaIngresos[INCOME STATEMENT - REVENUE SECTION],"<"&DATE(2026,12,1)) | M9: =SUMIFS(TablaIngresos[Amount],TablaIngresos[Category],$A9,TablaIngresos[INCOME STATEMENT - REVENUE SECTION],">="&DATE(2026,12,1),TablaIngresos[INCOME STATEMENT - REVENUE SECTION],"<"&DATE(2027,1,1)) | N9: =SUM(B9:M9)
A10: Capital gains | B10: =SUMIFS(TablaIngresos[Amount],TablaIngresos[Category],$A10,TablaIngresos[INCOME STATEMENT - REVENUE SECTION],">="&DATE(2026,1,1),TablaIngresos[INCOME STATEMENT - REVENUE SECTION],"<"&DATE(2026,2,1)) | C10: =SUMIFS(TablaIngresos[Amount],TablaIngresos[Category],$A10,TablaIngresos[INCOME STATEMENT - REVENUE SECTION],">="&DATE(2026,2,1),TablaIngresos[INCOME STATEMENT - REVENUE SECTION],"<"&DATE(2026,3,1)) | D10: =SUMIFS(TablaIngresos[Amount],TablaIngresos[Category],$A10,TablaIngresos[INCOME STATEMENT - REVENUE SECTION],">="&DATE(2026,3,1),TablaIngresos[INCOME STATEMENT - REVENUE SECTION],"<"&DATE(2026,4,1)) | E10: =SUMIFS(TablaIngresos[Amount],TablaIngresos[Category],$A10,TablaIngresos[INCOME STATEMENT - REVENUE SECTION],">="&DATE(2026,4,1),TablaIngresos[INCOME STATEMENT - REVENUE SECTION],"<"&DATE(2026,5,1)) | F10: =SUMIFS(TablaIngresos[Amount],TablaIngresos[Category],$A10,TablaIngresos[INCOME STATEMENT - REVENUE SECTION],">="&DATE(2026,5,1),TablaIngresos[INCOME STATEMENT - REVENUE SECTION],"<"&DATE(2026,6,1)) | G10: =SUMIFS(TablaIngresos[Amount],TablaIngresos[Category],$A10,TablaIngresos[INCOME STATEMENT - REVENUE SECTION],">="&DATE(2026,6,1),TablaIngresos[INCOME STATEMENT - REVENUE SECTION],"<"&DATE(2026,7,1)) | H10: =SUMIFS(TablaIngresos[Amount],TablaIngresos[Category],$A10,TablaIngresos[INCOME STATEMENT - REVENUE SECTION],">="&DATE(2026,7,1),TablaIngresos[INCOME STATEMENT - REVENUE SECTION],"<"&DATE(2026,8,1)) | I10: =SUMIFS(TablaIngresos[Amount],TablaIngresos[Category],$A10,TablaIngresos[INCOME STATEMENT - REVENUE SECTION],">="&DATE(2026,8,1),TablaIngresos[INCOME STATEMENT - REVENUE SECTION],"<"&DATE(2026,9,1)) | J10: =SUMIFS(TablaIngresos[Amount],TablaIngresos[Category],$A10,TablaIngresos[INCOME STATEMENT - REVENUE SECTION],">="&DATE(2026,9,1),TablaIngresos[INCOME STATEMENT - REVENUE SECTION],"<"&DATE(2026,10,1)) | K10: =SUMIFS(TablaIngresos[Amount],TablaIngresos[Category],$A10,TablaIngresos[INCOME STATEMENT - REVENUE SECTION],">="&DATE(2026,10,1),TablaIngresos[INCOME STATEMENT - REVENUE SECTION],"<"&DATE(2026,11,1)) | L10: =SUMIFS(TablaIngresos[Amount],TablaIngresos[Category],$A10,TablaIngresos[INCOME STATEMENT - REVENUE SECTION],">="&DATE(2026,11,1),TablaIngresos[INCOME STATEMENT - REVENUE SECTION],"<"&DATE(2026,12,1)) | M10: =SUMIFS(TablaIngresos[Amount],TablaIngresos[Category],$A10,TablaIngresos[INCOME STATEMENT - REVENUE SECTION],">="&DATE(2026,12,1),TablaIngresos[INCOME STATEMENT - REVENUE SECTION],"<"&DATE(2027,1,1)) | N10: =SUM(B10:M10)
A11: TOTAL REVENUE | B11: =SUM(B6:B10) | C11: =SUM(C6:C10) | D11: =SUM(D6:D10) | E11: =SUM(E6:E10) | F11: =SUM(F6:F10) | G11: =SUM(G6:G10) | H11: =SUM(H6:H10) | I11: =SUM(I6:I10) | ... M11: =SUM(M6:M10) | N11: =SUM(B11:M11)
A13: EXPENSES / GASTOS
A14: Advertising | B14: =SUMIFS(TablaGastos[Amount],TablaGastos[Category],$A14,TablaGastos[Date],">="&DATE(2026,1,1),TablaGastos[Date],"<"&DATE(2026,2,1)) | C14: =SUMIFS(TablaGastos[Amount],TablaGastos[Category],$A14,TablaGastos[Date],">="&DATE(2026,2,1),TablaGastos[Date],"<"&DATE(2026,3,1)) | D14: =SUMIFS(TablaGastos[Amount],TablaGastos[Category],$A14,TablaGastos[Date],">="&DATE(2026,3,1),TablaGastos[Date],"<"&DATE(2026,4,1)) | E14: =SUMIFS(TablaGastos[Amount],TablaGastos[Category],$A14,TablaGastos[Date],">="&DATE(2026,4,1),TablaGastos[Date],"<"&DATE(2026,5,1)) | F14: =SUMIFS(TablaGastos[Amount],TablaGastos[Category],$A14,TablaGastos[Date],">="&DATE(2026,5,1),TablaGastos[Date],"<"&DATE(2026,6,1)) | G14: =SUMIFS(TablaGastos[Amount],TablaGastos[Category],$A14,TablaGastos[Date],">="&DATE(2026,6,1),TablaGastos[Date],"<"&DATE(2026,7,1)) | H14: =SUMIFS(TablaGastos[Amount],TablaGastos[Category],$A14,TablaGastos[Date],">="&DATE(2026,7,1),TablaGastos[Date],"<"&DATE(2026,8,1)) | I14: =SUMIFS(TablaGastos[Amount],TablaGastos[Category],$A14,TablaGastos[Date],">="&DATE(2026,8,1),TablaGastos[Date],"<"&DATE(2026,9,1)) | J14: =SUMIFS(TablaGastos[Amount],TablaGastos[Category],$A14,TablaGastos[Date],">="&DATE(2026,9,1),TablaGastos[Date],"<"&DATE(2026,10,1)) | K14: =SUMIFS(TablaGastos[Amount],TablaGastos[Category],$A14,TablaGastos[Date],">="&DATE(2026,10,1),TablaGastos[Date],"<"&DATE(2026,11,1)) | L14: =SUMIFS(TablaGastos[Amount],TablaGastos[Category],$A14,TablaGastos[Date],">="&DATE(2026,11,1),TablaGastos[Date],"<"&DATE(2026,12,1)) | M14: =SUMIFS(TablaGastos[Amount],TablaGastos[Category],$A14,TablaGastos[Date],">="&DATE(2026,12,1),TablaGastos[Date],"<"&DATE(2027,1,1)) | N14: =SUM(B14:M14)
A15: Bad debts | B15: =SUMIFS(TablaGastos[Amount],TablaGastos[Category],$A15,TablaGastos[Date],">="&DATE(2026,1,1),TablaGastos[Date],"<"&DATE(2026,2,1)) | C15: =SUMIFS(TablaGastos[Amount],TablaGastos[Category],$A15,TablaGastos[Date],">="&DATE(2026,2,1),TablaGastos[Date],"<"&DATE(2026,3,1)) | D15: =SUMIFS(TablaGastos[Amount],TablaGastos[Category],$A15,TablaGastos[Date],">="&DATE(2026,3,1),TablaGastos[Date],"<"&DATE(2026,4,1)) | E15: =SUMIFS(TablaGastos[Amount],TablaGastos[Category],$A15,TablaGastos[Date],">="&DATE(2026,4,1),TablaGastos[Date],"<"&DATE(2026,5,1)) | F15: =SUMIFS(TablaGastos[Amount],TablaGastos[Category],$A15,TablaGastos[Date],">="&DATE(2026,5,1),TablaGastos[Date],"<"&DATE(2026,6,1)) | G15: =SUMIFS(TablaGastos[Amount],TablaGastos[Category],$A15,TablaGastos[Date],">="&DATE(2026,6,1),TablaGastos[Date],"<"&DATE(2026,7,1)) | H15: =SUMIFS(TablaGastos[Amount],TablaGastos[Category],$A15,TablaGastos[Date],">="&DATE(2026,7,1),TablaGastos[Date],"<"&DATE(2026,8,1)) | I15: =SUMIFS(TablaGastos[Amount],TablaGastos[Category],$A15,TablaGastos[Date],">="&DATE(2026,8,1),TablaGastos[Date],"<"&DATE(2026,9,1)) | J15: =SUMIFS(TablaGastos[Amount],TablaGastos[Category],$A15,TablaGastos[Date],">="&DATE(2026,9,1),TablaGastos[Date],"<"&DATE(2026,10,1)) | K15: =SUMIFS(TablaGastos[Amount],TablaGastos[Category],$A15,TablaGastos[Date],">="&DATE(2026,10,1),TablaGastos[Date],"<"&DATE(2026,11,1)) | L15: =SUMIFS(TablaGastos[Amount],TablaGastos[Category],$A15,TablaGastos[Date],">="&DATE(2026,11,1),TablaGastos[Date],"<"&DATE(2026,12,1)) | M15: =SUMIFS(TablaGastos[Amount],TablaGastos[Category],$A15,TablaGastos[Date],">="&DATE(2026,12,1),TablaGastos[Date],"<"&DATE(2027,1,1)) | N15: =SUM(B15:M15)
A16: Car and truck expenses | B16: =SUMIFS(TablaGastos[Amount],TablaGastos[Category],$A16,TablaGastos[Date],">="&DATE(2026,1,1),TablaGastos[Date],"<"&DATE(2026,2,1)) | C16: =SUMIFS(TablaGastos[Amount],TablaGastos[Category],$A16,TablaGastos[Date],">="&DATE(2026,2,1),TablaGastos[Date],"<"&DATE(2026,3,1)) | D16: =SUMIFS(TablaGastos[Amount],TablaGastos[Category],$A16,TablaGastos[Date],">="&DATE(2026,3,1),TablaGastos[Date],"<"&DATE(2026,4,1)) | E16: =SUMIFS(TablaGastos[Amount],TablaGastos[Category],$A16,TablaGastos[Date],">="&DATE(2026,4,1),TablaGastos[Date],"<"&DATE(2026,5,1)) | F16: =SUMIFS(TablaGastos[Amount],TablaGastos[Category],$A16,TablaGastos[Date],">="&DATE(2026,5,1),TablaGastos[Date],"<"&DATE(2026,6,1)) | G16: =SUMIFS(TablaGastos[Amount],TablaGastos[Category],$A16,TablaGastos[Date],">="&DATE(2026,6,1),TablaGastos[Date],"<"&DATE(2026,7,1)) | H16: =SUMIFS(TablaGastos[Amount],TablaGastos[Category],$A16,TablaGastos[Date],">="&DATE(2026,7,1),TablaGastos[Date],"<"&DATE(2026,8,1)) | I16: =SUMIFS(TablaGastos[Amount],TablaGastos[Category],$A16,TablaGastos[Date],">="&DATE(2026,8,1),TablaGastos[Date],"<"&DATE(2026,9,1)) | J16: =SUMIFS(TablaGastos[Amount],TablaGastos[Category],$A16,TablaGastos[Date],">="&DATE(2026,9,1),TablaGastos[Date],"<"&DATE(2026,10,1)) | K16: =SUMIFS(TablaGastos[Amount],TablaGastos[Category],$A16,TablaGastos[Date],">="&DATE(2026,10,1),TablaGastos[Date],"<"&DATE(2026,11,1)) | L16: =SUMIFS(TablaGastos[Amount],TablaGastos[Category],$A16,TablaGastos[Date],">="&DATE(2026,11,1),TablaGastos[Date],"<"&DATE(2026,12,1)) | M16: =SUMIFS(TablaGastos[Amount],TablaGastos[Category],$A16,TablaGastos[Date],">="&DATE(2026,12,1),TablaGastos[Date],"<"&DATE(2027,1,1)) | N16: =SUM(B16:M16)
A17: Commissions and fees | B17: =SUMIFS(TablaGastos[Amount],TablaGastos[Category],$A17,TablaGastos[Date],">="&DATE(2026,1,1),TablaGastos[Date],"<"&DATE(2026,2,1)) | C17: =SUMIFS(TablaGastos[Amount],TablaGastos[Category],$A17,TablaGastos[Date],">="&DATE(2026,2,1),TablaGastos[Date],"<"&DATE(2026,3,1)) | D17: =SUMIFS(TablaGastos[Amount],TablaGastos[Category],$A17,TablaGastos[Date],">="&DATE(2026,3,1),TablaGastos[Date],"<"&DATE(2026,4,1)) | E17: =SUMIFS(TablaGastos[Amount],TablaGastos[Category],$A17,TablaGastos[Date],">="&DATE(2026,4,1),TablaGastos[Date],"<"&DATE(2026,5,1)) | F17: =SUMIFS(TablaGastos[Amount],TablaGastos[Category],$A17,TablaGastos[Date],">="&DATE(2026,5,1),TablaGastos[Date],"<"&DATE(2026,6,1)) | G17: =SUMIFS(TablaGastos[Amount],TablaGastos[Category],$A17,TablaGastos[Date],">="&DATE(2026,6,1),TablaGastos[Date],"<"&DATE(2026,7,1)) | H17: =SUMIFS(TablaGastos[Amount],TablaGastos[Category],$A17,TablaGastos[Date],">="&DATE(2026,7,1),TablaGastos[Date],"<"&DATE(2026,8,1)) | I17: =SUMIFS(TablaGastos[Amount],TablaGastos[Category],$A17,TablaGastos[Date],">="&DATE(2026,8,1),TablaGastos[Date],"<"&DATE(2026,9,1)) | J17: =SUMIFS(TablaGastos[Amount],TablaGastos[Category],$A17,TablaGastos[Date],">="&DATE(2026,9,1),TablaGastos[Date],"<"&DATE(2026,10,1)) | K17: =SUMIFS(TablaGastos[Amount],TablaGastos[Category],$A17,TablaGastos[Date],">="&DATE(2026,10,1),TablaGastos[Date],"<"&DATE(2026,11,1)) | L17: =SUMIFS(TablaGastos[Amount],TablaGastos[Category],$A17,TablaGastos[Date],">="&DATE(2026,11,1),TablaGastos[Date],"<"&DATE(2026,12,1)) | M17: =SUMIFS(TablaGastos[Amount],TablaGastos[Category],$A17,TablaGastos[Date],">="&DATE(2026,12,1),TablaGastos[Date],"<"&DATE(2027,1,1)) | N17: =SUM(B17:M17)
A18: Compensation of officers | B18: =SUMIFS(TablaGastos[Amount],TablaGastos[Category],$A18,TablaGastos[Date],">="&DATE(2026,1,1),TablaGastos[Date],"<"&DATE(2026,2,1)) | C18: =SUMIFS(TablaGastos[Amount],TablaGastos[Category],$A18,TablaGastos[Date],">="&DATE(2026,2,1),TablaGastos[Date],"<"&DATE(2026,3,1)) | D18: =SUMIFS(TablaGastos[Amount],TablaGastos[Category],$A18,TablaGastos[Date],">="&DATE(2026,3,1),TablaGastos[Date],"<"&DATE(2026,4,1)) | E18: =SUMIFS(TablaGastos[Amount],TablaGastos[Category],$A18,TablaGastos[Date],">="&DATE(2026,4,1),TablaGastos[Date],"<"&DATE(2026,5,1)) | F18: =SUMIFS(TablaGastos[Amount],TablaGastos[Category],$A18,TablaGastos[Date],">="&DATE(2026,5,1),TablaGastos[Date],"<"&DATE(2026,6,1)) | G18: =SUMIFS(TablaGastos[Amount],TablaGastos[Category],$A18,TablaGastos[Date],">="&DATE(2026,6,1),TablaGastos[Date],"<"&DATE(2026,7,1)) | H18: =SUMIFS(TablaGastos[Amount],TablaGastos[Category],$A18,TablaGastos[Date],">="&DATE(2026,7,1),TablaGastos[Date],"<"&DATE(2026,8,1)) | I18: =SUMIFS(TablaGastos[Amount],TablaGastos[Category],$A18,TablaGastos[Date],">="&DATE(2026,8,1),TablaGastos[Date],"<"&DATE(2026,9,1)) | J18: =SUMIFS(TablaGastos[Amount],TablaGastos[Category],$A18,TablaGastos[Date],">="&DATE(2026,9,1),TablaGastos[Date],"<"&DATE(2026,10,1)) | K18: =SUMIFS(TablaGastos[Amount],TablaGastos[Category],$A18,TablaGastos[Date],">="&DATE(2026,10,1),TablaGastos[Date],"<"&DATE(2026,11,1)) | L18: =SUMIFS(TablaGastos[Amount],TablaGastos[Category],$A18,TablaGastos[Date],">="&DATE(2026,11,1),TablaGastos[Date],"<"&DATE(2026,12,1)) | M18: =SUMIFS(TablaGastos[Amount],TablaGastos[Category],$A18,TablaGastos[Date],">="&DATE(2026,12,1),TablaGastos[Date],"<"&DATE(2027,1,1)) | N18: =SUM(B18:M18)
A19: Contract labor | B19: =SUMIFS(TablaGastos[Amount],TablaGastos[Category],$A19,TablaGastos[Date],">="&DATE(2026,1,1),TablaGastos[Date],"<"&DATE(2026,2,1)) | C19: =SUMIFS(TablaGastos[Amount],TablaGastos[Category],$A19,TablaGastos[Date],">="&DATE(2026,2,1),TablaGastos[Date],"<"&DATE(2026,3,1)) | D19: =SUMIFS(TablaGastos[Amount],TablaGastos[Category],$A19,TablaGastos[Date],">="&DATE(2026,3,1),TablaGastos[Date],"<"&DATE(2026,4,1)) | E19: =SUMIFS(TablaGastos[Amount],TablaGastos[Category],$A19,TablaGastos[Date],">="&DATE(2026,4,1),TablaGastos[Date],"<"&DATE(2026,5,1)) | F19: =SUMIFS(TablaGastos[Amount],TablaGastos[Category],$A19,TablaGastos[Date],">="&DATE(2026,5,1),TablaGastos[Date],"<"&DATE(2026,6,1)) | G19: =SUMIFS(TablaGastos[Amount],TablaGastos[Category],$A19,TablaGastos[Date],">="&DATE(2026,6,1),TablaGastos[Date],"<"&DATE(2026,7,1)) | H19: =SUMIFS(TablaGastos[Amount],TablaGastos[Category],$A19,TablaGastos[Date],">="&DATE(2026,7,1),TablaGastos[Date],"<"&DATE(2026,8,1)) | I19: =SUMIFS(TablaGastos[Amount],TablaGastos[Category],$A19,TablaGastos[Date],">="&DATE(2026,8,1),TablaGastos[Date],"<"&DATE(2026,9,1)) | J19: =SUMIFS(TablaGastos[Amount],TablaGastos[Category],$A19,TablaGastos[Date],">="&DATE(2026,9,1),TablaGastos[Date],"<"&DATE(2026,10,1)) | K19: =SUMIFS(TablaGastos[Amount],TablaGastos[Category],$A19,TablaGastos[Date],">="&DATE(2026,10,1),TablaGastos[Date],"<"&DATE(2026,11,1)) | L19: =SUMIFS(TablaGastos[Amount],TablaGastos[Category],$A19,TablaGastos[Date],">="&DATE(2026,11,1),TablaGastos[Date],"<"&DATE(2026,12,1)) | M19: =SUMIFS(TablaGastos[Amount],TablaGastos[Category],$A19,TablaGastos[Date],">="&DATE(2026,12,1),TablaGastos[Date],"<"&DATE(2027,1,1)) | N19: =SUM(B19:M19)
A20: Cost of goods sold | B20: =SUMIFS(TablaGastos[Amount],TablaGastos[Category],$A20,TablaGastos[Date],">="&DATE(2026,1,1),TablaGastos[Date],"<"&DATE(2026,2,1)) | C20: =SUMIFS(TablaGastos[Amount],TablaGastos[Category],$A20,TablaGastos[Date],">="&DATE(2026,2,1),TablaGastos[Date],"<"&DATE(2026,3,1)) | D20: =SUMIFS(TablaGastos[Amount],TablaGastos[Category],$A20,TablaGastos[Date],">="&DATE(2026,3,1),TablaGastos[Date],"<"&DATE(2026,4,1)) | E20: =SUMIFS(TablaGastos[Amount],TablaGastos[Category],$A20,TablaGastos[Date],">="&DATE(2026,4,1),TablaGastos[Date],"<"&DATE(2026,5,1)) | F20: =SUMIFS(TablaGastos[Amount],TablaGastos[Category],$A20,TablaGastos[Date],">="&DATE(2026,5,1),TablaGastos[Date],"<"&DATE(2026,6,1)) | G20: =SUMIFS(TablaGastos[Amount],TablaGastos[Category],$A20,TablaGastos[Date],">="&DATE(2026,6,1),TablaGastos[Date],"<"&DATE(2026,7,1)) | H20: =SUMIFS(TablaGastos[Amount],TablaGastos[Category],$A20,TablaGastos[Date],">="&DATE(2026,7,1),TablaGastos[Date],"<"&DATE(2026,8,1)) | I20: =SUMIFS(TablaGastos[Amount],TablaGastos[Category],$A20,TablaGastos[Date],">="&DATE(2026,8,1),TablaGastos[Date],"<"&DATE(2026,9,1)) | J20: =SUMIFS(TablaGastos[Amount],TablaGastos[Category],$A20,TablaGastos[Date],">="&DATE(2026,9,1),TablaGastos[Date],"<"&DATE(2026,10,1)) | K20: =SUMIFS(TablaGastos[Amount],TablaGastos[Category],$A20,TablaGastos[Date],">="&DATE(2026,10,1),TablaGastos[Date],"<"&DATE(2026,11,1)) | L20: =SUMIFS(TablaGastos[Amount],TablaGastos[Category],$A20,TablaGastos[Date],">="&DATE(2026,11,1),TablaGastos[Date],"<"&DATE(2026,12,1)) | M20: =SUMIFS(TablaGastos[Amount],TablaGastos[Category],$A20,TablaGastos[Date],">="&DATE(2026,12,1),TablaGastos[Date],"<"&DATE(2027,1,1)) | N20: =SUM(B20:M20)
A21: Deductible meals | B21: =SUMIFS(TablaGastos[Amount],TablaGastos[Category],$A21,TablaGastos[Date],">="&DATE(2026,1,1),TablaGastos[Date],"<"&DATE(2026,2,1)) | C21: =SUMIFS(TablaGastos[Amount],TablaGastos[Category],$A21,TablaGastos[Date],">="&DATE(2026,2,1),TablaGastos[Date],"<"&DATE(2026,3,1)) | D21: =SUMIFS(TablaGastos[Amount],TablaGastos[Category],$A21,TablaGastos[Date],">="&DATE(2026,3,1),TablaGastos[Date],"<"&DATE(2026,4,1)) | E21: =SUMIFS(TablaGastos[Amount],TablaGastos[Category],$A21,TablaGastos[Date],">="&DATE(2026,4,1),TablaGastos[Date],"<"&DATE(2026,5,1)) | F21: =SUMIFS(TablaGastos[Amount],TablaGastos[Category],$A21,TablaGastos[Date],">="&DATE(2026,5,1),TablaGastos[Date],"<"&DATE(2026,6,1)) | G21: =SUMIFS(TablaGastos[Amount],TablaGastos[Category],$A21,TablaGastos[Date],">="&DATE(2026,6,1),TablaGastos[Date],"<"&DATE(2026,7,1)) | H21: =SUMIFS(TablaGastos[Amount],TablaGastos[Category],$A21,TablaGastos[Date],">="&DATE(2026,7,1),TablaGastos[Date],"<"&DATE(2026,8,1)) | I21: =SUMIFS(TablaGastos[Amount],TablaGastos[Category],$A21,TablaGastos[Date],">="&DATE(2026,8,1),TablaGastos[Date],"<"&DATE(2026,9,1)) | J21: =SUMIFS(TablaGastos[Amount],TablaGastos[Category],$A21,TablaGastos[Date],">="&DATE(2026,9,1),TablaGastos[Date],"<"&DATE(2026,10,1)) | K21: =SUMIFS(TablaGastos[Amount],TablaGastos[Category],$A21,TablaGastos[Date],">="&DATE(2026,10,1),TablaGastos[Date],"<"&DATE(2026,11,1)) | L21: =SUMIFS(TablaGastos[Amount],TablaGastos[Category],$A21,TablaGastos[Date],">="&DATE(2026,11,1),TablaGastos[Date],"<"&DATE(2026,12,1)) | M21: =SUMIFS(TablaGastos[Amount],TablaGastos[Category],$A21,TablaGastos[Date],">="&DATE(2026,12,1),TablaGastos[Date],"<"&DATE(2027,1,1)) | N21: =SUM(B21:M21)
A22: Depreciation | B22: =SUMIFS(TablaGastos[Amount],TablaGastos[Category],$A22,TablaGastos[Date],">="&DATE(2026,1,1),TablaGastos[Date],"<"&DATE(2026,2,1)) | C22: =SUMIFS(TablaGastos[Amount],TablaGastos[Category],$A22,TablaGastos[Date],">="&DATE(2026,2,1),TablaGastos[Date],"<"&DATE(2026,3,1)) | D22: =SUMIFS(TablaGastos[Amount],TablaGastos[Category],$A22,TablaGastos[Date],">="&DATE(2026,3,1),TablaGastos[Date],"<"&DATE(2026,4,1)) | E22: =SUMIFS(TablaGastos[Amount],TablaGastos[Category],$A22,TablaGastos[Date],">="&DATE(2026,4,1),TablaGastos[Date],"<"&DATE(2026,5,1)) | F22: =SUMIFS(TablaGastos[Amount],TablaGastos[Category],$A22,TablaGastos[Date],">="&DATE(2026,5,1),TablaGastos[Date],"<"&DATE(2026,6,1)) | G22: =SUMIFS(TablaGastos[Amount],TablaGastos[Category],$A22,TablaGastos[Date],">="&DATE(2026,6,1),TablaGastos[Date],"<"&DATE(2026,7,1)) | H22: =SUMIFS(TablaGastos[Amount],TablaGastos[Category],$A22,TablaGastos[Date],">="&DATE(2026,7,1),TablaGastos[Date],"<"&DATE(2026,8,1)) | I22: =SUMIFS(TablaGastos[Amount],TablaGastos[Category],$A22,TablaGastos[Date],">="&DATE(2026,8,1),TablaGastos[Date],"<"&DATE(2026,9,1)) | J22: =SUMIFS(TablaGastos[Amount],TablaGastos[Category],$A22,TablaGastos[Date],">="&DATE(2026,9,1),TablaGastos[Date],"<"&DATE(2026,10,1)) | K22: =SUMIFS(TablaGastos[Amount],TablaGastos[Category],$A22,TablaGastos[Date],">="&DATE(2026,10,1),TablaGastos[Date],"<"&DATE(2026,11,1)) | L22: =SUMIFS(TablaGastos[Amount],TablaGastos[Category],$A22,TablaGastos[Date],">="&DATE(2026,11,1),TablaGastos[Date],"<"&DATE(2026,12,1)) | M22: =SUMIFS(TablaGastos[Amount],TablaGastos[Category],$A22,TablaGastos[Date],">="&DATE(2026,12,1),TablaGastos[Date],"<"&DATE(2027,1,1)) | N22: =SUM(B22:M22)
A23: Employee benefit programs | B23: =SUMIFS(TablaGastos[Amount],TablaGastos[Category],$A23,TablaGastos[Date],">="&DATE(2026,1,1),TablaGastos[Date],"<"&DATE(2026,2,1)) | C23: =SUMIFS(TablaGastos[Amount],TablaGastos[Category],$A23,TablaGastos[Date],">="&DATE(2026,2,1),TablaGastos[Date],"<"&DATE(2026,3,1)) | D23: =SUMIFS(TablaGastos[Amount],TablaGastos[Category],$A23,TablaGastos[Date],">="&DATE(2026,3,1),TablaGastos[Date],"<"&DATE(2026,4,1)) | E23: =SUMIFS(TablaGastos[Amount],TablaGastos[Category],$A23,TablaGastos[Date],">="&DATE(2026,4,1),TablaGastos[Date],"<"&DATE(2026,5,1)) | F23: =SUMIFS(TablaGastos[Amount],TablaGastos[Category],$A23,TablaGastos[Date],">="&DATE(2026,5,1),TablaGastos[Date],"<"&DATE(2026,6,1)) | G23: =SUMIFS(TablaGastos[Amount],TablaGastos[Category],$A23,TablaGastos[Date],">="&DATE(2026,6,1),TablaGastos[Date],"<"&DATE(2026,7,1)) | H23: =SUMIFS(TablaGastos[Amount],TablaGastos[Category],$A23,TablaGastos[Date],">="&DATE(2026,7,1),TablaGastos[Date],"<"&DATE(2026,8,1)) | I23: =SUMIFS(TablaGastos[Amount],TablaGastos[Category],$A23,TablaGastos[Date],">="&DATE(2026,8,1),TablaGastos[Date],"<"&DATE(2026,9,1)) | J23: =SUMIFS(TablaGastos[Amount],TablaGastos[Category],$A23,TablaGastos[Date],">="&DATE(2026,9,1),TablaGastos[Date],"<"&DATE(2026,10,1)) | K23: =SUMIFS(TablaGastos[Amount],TablaGastos[Category],$A23,TablaGastos[Date],">="&DATE(2026,10,1),TablaGastos[Date],"<"&DATE(2026,11,1)) | L23: =SUMIFS(TablaGastos[Amount],TablaGastos[Category],$A23,TablaGastos[Date],">="&DATE(2026,11,1),TablaGastos[Date],"<"&DATE(2026,12,1)) | M23: =SUMIFS(TablaGastos[Amount],TablaGastos[Category],$A23,TablaGastos[Date],">="&DATE(2026,12,1),TablaGastos[Date],"<"&DATE(2027,1,1)) | N23: =SUM(B23:M23)
A24: Insurance | B24: =SUMIFS(TablaGastos[Amount],TablaGastos[Category],$A24,TablaGastos[Date],">="&DATE(2026,1,1),TablaGastos[Date],"<"&DATE(2026,2,1)) | C24: =SUMIFS(TablaGastos[Amount],TablaGastos[Category],$A24,TablaGastos[Date],">="&DATE(2026,2,1),TablaGastos[Date],"<"&DATE(2026,3,1)) | D24: =SUMIFS(TablaGastos[Amount],TablaGastos[Category],$A24,TablaGastos[Date],">="&DATE(2026,3,1),TablaGastos[Date],"<"&DATE(2026,4,1)) | E24: =SUMIFS(TablaGastos[Amount],TablaGastos[Category],$A24,TablaGastos[Date],">="&DATE(2026,4,1),TablaGastos[Date],"<"&DATE(2026,5,1)) | F24: =SUMIFS(TablaGastos[Amount],TablaGastos[Category],$A24,TablaGastos[Date],">="&DATE(2026,5,1),TablaGastos[Date],"<"&DATE(2026,6,1)) | G24: =SUMIFS(TablaGastos[Amount],TablaGastos[Category],$A24,TablaGastos[Date],">="&DATE(2026,6,1),TablaGastos[Date],"<"&DATE(2026,7,1)) | H24: =SUMIFS(TablaGastos[Amount],TablaGastos[Category],$A24,TablaGastos[Date],">="&DATE(2026,7,1),TablaGastos[Date],"<"&DATE(2026,8,1)) | I24: =SUMIFS(TablaGastos[Amount],TablaGastos[Category],$A24,TablaGastos[Date],">="&DATE(2026,8,1),TablaGastos[Date],"<"&DATE(2026,9,1)) | J24: =SUMIFS(TablaGastos[Amount],TablaGastos[Category],$A24,TablaGastos[Date],">="&DATE(2026,9,1),TablaGastos[Date],"<"&DATE(2026,10,1)) | K24: =SUMIFS(TablaGastos[Amount],TablaGastos[Category],$A24,TablaGastos[Date],">="&DATE(2026,10,1),TablaGastos[Date],"<"&DATE(2026,11,1)) | L24: =SUMIFS(TablaGastos[Amount],TablaGastos[Category],$A24,TablaGastos[Date],">="&DATE(2026,11,1),TablaGastos[Date],"<"&DATE(2026,12,1)) | M24: =SUMIFS(TablaGastos[Amount],TablaGastos[Category],$A24,TablaGastos[Date],">="&DATE(2026,12,1),TablaGastos[Date],"<"&DATE(2027,1,1)) | N24: =SUM(B24:M24)
A25: Interest | B25: =SUMIFS(TablaGastos[Amount],TablaGastos[Category],$A25,TablaGastos[Date],">="&DATE(2026,1,1),TablaGastos[Date],"<"&DATE(2026,2,1)) | C25: =SUMIFS(TablaGastos[Amount],TablaGastos[Category],$A25,TablaGastos[Date],">="&DATE(2026,2,1),TablaGastos[Date],"<"&DATE(2026,3,1)) | D25: =SUMIFS(TablaGastos[Amount],TablaGastos[Category],$A25,TablaGastos[Date],">="&DATE(2026,3,1),TablaGastos[Date],"<"&DATE(2026,4,1)) | E25: =SUMIFS(TablaGastos[Amount],TablaGastos[Category],$A25,TablaGastos[Date],">="&DATE(2026,4,1),TablaGastos[Date],"<"&DATE(2026,5,1)) | F25: =SUMIFS(TablaGastos[Amount],TablaGastos[Category],$A25,TablaGastos[Date],">="&DATE(2026,5,1),TablaGastos[Date],"<"&DATE(2026,6,1)) | G25: =SUMIFS(TablaGastos[Amount],TablaGastos[Category],$A25,TablaGastos[Date],">="&DATE(2026,6,1),TablaGastos[Date],"<"&DATE(2026,7,1)) | H25: =SUMIFS(TablaGastos[Amount],TablaGastos[Category],$A25,TablaGastos[Date],">="&DATE(2026,7,1),TablaGastos[Date],"<"&DATE(2026,8,1)) | I25: =SUMIFS(TablaGastos[Amount],TablaGastos[Category],$A25,TablaGastos[Date],">="&DATE(2026,8,1),TablaGastos[Date],"<"&DATE(2026,9,1)) | J25: =SUMIFS(TablaGastos[Amount],TablaGastos[Category],$A25,TablaGastos[Date],">="&DATE(2026,9,1),TablaGastos[Date],"<"&DATE(2026,10,1)) | K25: =SUMIFS(TablaGastos[Amount],TablaGastos[Category],$A25,TablaGastos[Date],">="&DATE(2026,10,1),TablaGastos[Date],"<"&DATE(2026,11,1)) | L25: =SUMIFS(TablaGastos[Amount],TablaGastos[Category],$A25,TablaGastos[Date],">="&DATE(2026,11,1),TablaGastos[Date],"<"&DATE(2026,12,1)) | M25: =SUMIFS(TablaGastos[Amount],TablaGastos[Category],$A25,TablaGastos[Date],">="&DATE(2026,12,1),TablaGastos[Date],"<"&DATE(2027,1,1)) | N25: =SUM(B25:M25)
... A35: Other expenses | B35: =SUMIFS(TablaGastos[Amount],TablaGastos[Category],$A35,TablaGastos[Date],">="&DATE(2026,1,1),TablaGastos[Date],"<"&DATE(2026,2,1)) | C35: =SUMIFS(TablaGastos[Amount],TablaGastos[Category],$A35,TablaGastos[Date],">="&DATE(2026,2,1),TablaGastos[Date],"<"&DATE(2026,3,1)) | D35: =SUMIFS(TablaGastos[Amount],TablaGastos[Category],$A35,TablaGastos[Date],">="&DATE(2026,3,1),TablaGastos[Date],"<"&DATE(2026,4,1)) | E35: =SUMIFS(TablaGastos[Amount],TablaGastos[Category],$A35,TablaGastos[Date],">="&DATE(2026,4,1),TablaGastos[Date],"<"&DATE(2026,5,1)) | F35: =SUMIFS(TablaGastos[Amount],TablaGastos[Category],$A35,TablaGastos[Date],">="&DATE(2026,5,1),TablaGastos[Date],"<"&DATE(2026,6,1)) | G35: =SUMIFS(TablaGastos[Amount],TablaGastos[Category],$A35,TablaGastos[Date],">="&DATE(2026,6,1),TablaGastos[Date],"<"&DATE(2026,7,1)) | H35: =SUMIFS(TablaGastos[Amount],TablaGastos[Category],$A35,TablaGastos[Date],">="&DATE(2026,7,1),TablaGastos[Date],"<"&DATE(2026,8,1)) | I35: =SUMIFS(TablaGastos[Amount],TablaGastos[Category],$A35,TablaGastos[Date],">="&DATE(2026,8,1),TablaGastos[Date],"<"&DATE(2026,9,1)) | J35: =SUMIFS(TablaGastos[Amount],TablaGastos[Category],$A35,TablaGastos[Date],">="&DATE(2026,9,1),TablaGastos[Date],"<"&DATE(2026,10,1)) | K35: =SUMIFS(TablaGastos[Amount],TablaGastos[Category],$A35,TablaGastos[Date],">="&DATE(2026,10,1),TablaGastos[Date],"<"&DATE(2026,11,1)) | L35: =SUMIFS(TablaGastos[Amount],TablaGastos[Category],$A35,TablaGastos[Date],">="&DATE(2026,11,1),TablaGastos[Date],"<"&DATE(2026,12,1)) | M35: =SUMIFS(TablaGastos[Amount],TablaGastos[Category],$A35,TablaGastos[Date],">="&DATE(2026,12,1),TablaGastos[Date],"<"&DATE(2027,1,1)) | N35: =SUM(B35:M35)
A37: NON-DEDUCTIBLE
A38: Owner's Distribution | B38: =SUMIFS(TablaGastos[Amount],TablaGastos[Category],"Owner's Distribution",TablaGastos[Date],">="&DATE(2026,1,1),TablaGastos[Date],"<"&DATE(2026,2,1)) | C38: =SUMIFS(TablaGastos[Amount],TablaGastos[Category],"Owner's Distribution",TablaGastos[Date],">="&DATE(2026,2,1),TablaGastos[Date],"<"&DATE(2026,3,1)) | D38: =SUMIFS(TablaGastos[Amount],TablaGastos[Category],"Owner's Distribution",TablaGastos[Date],">="&DATE(2026,3,1),TablaGastos[Date],"<"&DATE(2026,4,1)) | E38: =SUMIFS(TablaGastos[Amount],TablaGastos[Category],"Owner's Distribution",TablaGastos[Date],">="&DATE(2026,4,1),TablaGastos[Date],"<"&DATE(2026,5,1)) | F38: =SUMIFS(TablaGastos[Amount],TablaGastos[Category],"Owner's Distribution",TablaGastos[Date],">="&DATE(2026,5,1),TablaGastos[Date],"<"&DATE(2026,6,1)) | G38: =SUMIFS(TablaGastos[Amount],TablaGastos[Category],"Owner's Distribution",TablaGastos[Date],">="&DATE(2026,6,1),TablaGastos[Date],"<"&DATE(2026,7,1)) | H38: =SUMIFS(TablaGastos[Amount],TablaGastos[Category],"Owner's Distribution",TablaGastos[Date],">="&DATE(2026,7,1),TablaGastos[Date],"<"&DATE(2026,8,1)) | I38: =SUMIFS(TablaGastos[Amount],TablaGastos[Category],"Owner's Distribution",TablaGastos[Date],">="&DATE(2026,8,1),TablaGastos[Date],"<"&DATE(2026,9,1)) | J38: =SUMIFS(TablaGastos[Amount],TablaGastos[Category],"Owner's Distribution",TablaGastos[Date],">="&DATE(2026,9,1),TablaGastos[Date],"<"&DATE(2026,10,1)) | K38: =SUMIFS(TablaGastos[Amount],TablaGastos[Category],"Owner's Distribution",TablaGastos[Date],">="&DATE(2026,10,1),TablaGastos[Date],"<"&DATE(2026,11,1)) | L38: =SUMIFS(TablaGastos[Amount],TablaGastos[Category],"Owner's Distribution",TablaGastos[Date],">="&DATE(2026,11,1),TablaGastos[Date],"<"&DATE(2026,12,1)) | M38: =SUMIFS(TablaGastos[Amount],TablaGastos[Category],"Owner's Distribution",TablaGastos[Date],">="&DATE(2026,12,1),TablaGastos[Date],"<"&DATE(2027,1,1)) | N38: =SUM(B38:M38)
A39: Loan - Principal | B39: =SUMIFS(TablaGastos[Amount],TablaGastos[Category],"Loan - Principal",TablaGastos[Date],">="&DATE(2026,1,1),TablaGastos[Date],"<"&DATE(2026,2,1)) | C39: =SUMIFS(TablaGastos[Amount],TablaGastos[Category],"Loan - Principal",TablaGastos[Date],">="&DATE(2026,2,1),TablaGastos[Date],"<"&DATE(2026,3,1)) | D39: =SUMIFS(TablaGastos[Amount],TablaGastos[Category],"Loan - Principal",TablaGastos[Date],">="&DATE(2026,3,1),TablaGastos[Date],"<"&DATE(2026,4,1)) | E39: =SUMIFS(TablaGastos[Amount],TablaGastos[Category],"Loan - Principal",TablaGastos[Date],">="&DATE(2026,4,1),TablaGastos[Date],"<"&DATE(2026,5,1)) | F39: =SUMIFS(TablaGastos[Amount],TablaGastos[Category],"Loan - Principal",TablaGastos[Date],">="&DATE(2026,5,1),TablaGastos[Date],"<"&DATE(2026,6,1)) | G39: =SUMIFS(TablaGastos[Amount],TablaGastos[Category],"Loan - Principal",TablaGastos[Date],">="&DATE(2026,6,1),TablaGastos[Date],"<"&DATE(2026,7,1)) | H39: =SUMIFS(TablaGastos[Amount],TablaGastos[Category],"Loan - Principal",TablaGastos[Date],">="&DATE(2026,7,1),TablaGastos[Date],"<"&DATE(2026,8,1)) | I39: =SUMIFS(TablaGastos[Amount],TablaGastos[Category],"Loan - Principal",TablaGastos[Date],">="&DATE(2026,8,1),TablaGastos[Date],"<"&DATE(2026,9,1)) | J39: =SUMIFS(TablaGastos[Amount],TablaGastos[Category],"Loan - Principal",TablaGastos[Date],">="&DATE(2026,9,1),TablaGastos[Date],"<"&DATE(2026,10,1)) | K39: =SUMIFS(TablaGastos[Amount],TablaGastos[Category],"Loan - Principal",TablaGastos[Date],">="&DATE(2026,10,1),TablaGastos[Date],"<"&DATE(2026,11,1)) | L39: =SUMIFS(TablaGastos[Amount],TablaGastos[Category],"Loan - Principal",TablaGastos[Date],">="&DATE(2026,11,1),TablaGastos[Date],"<"&DATE(2026,12,1)) | M39: =SUMIFS(TablaGastos[Amount],TablaGastos[Category],"Loan - Principal",TablaGastos[Date],">="&DATE(2026,12,1),TablaGastos[Date],"<"&DATE(2027,1,1)) | N39: =SUM(B39:M39)
A40: Returns and allowances | B40: =SUMIFS(TablaIngresos[Amount],TablaIngresos[Category],"Returns and allowances",TablaIngresos[INCOME STATEMENT - REVENUE SECTION],">="&DATE(2026,1,1),TablaIngresos[INCOME STATEMENT - REVENUE SECTION],"<"&DATE(2026,2,1)) | C40: =SUMIFS(TablaIngresos[Amount],TablaIngresos[Category],"Returns and allowances",TablaIngresos[INCOME STATEMENT - REVENUE SECTION],">="&DATE(2026,2,1),TablaIngresos[INCOME STATEMENT - REVENUE SECTION],"<"&DATE(2026,3,1)) | D40: =SUMIFS(TablaIngresos[Amount],TablaIngresos[Category],"Returns and allowances",TablaIngresos[INCOME STATEMENT - REVENUE SECTION],">="&DATE(2026,3,1),TablaIngresos[INCOME STATEMENT - REVENUE SECTION],"<"&DATE(2026,4,1)) | E40: =SUMIFS(TablaIngresos[Amount],TablaIngresos[Category],"Returns and allowances",TablaIngresos[INCOME STATEMENT - REVENUE SECTION],">="&DATE(2026,4,1),TablaIngresos[INCOME STATEMENT - REVENUE SECTION],"<"&DATE(2026,5,1)) | F40: =SUMIFS(TablaIngresos[Amount],TablaIngresos[Category],"Returns and allowances",TablaIngresos[INCOME STATEMENT - REVENUE SECTION],">="&DATE(2026,5,1),TablaIngresos[INCOME STATEMENT - REVENUE SECTION],"<"&DATE(2026,6,1)) | G40: =SUMIFS(TablaIngresos[Amount],TablaIngresos[Category],"Returns and allowances",TablaIngresos[INCOME STATEMENT - REVENUE SECTION],">="&DATE(2026,6,1),TablaIngresos[INCOME STATEMENT - REVENUE SECTION],"<"&DATE(2026,7,1)) | H40: =SUMIFS(TablaIngresos[Amount],TablaIngresos[Category],"Returns and allowances",TablaIngresos[INCOME STATEMENT - REVENUE SECTION],">="&DATE(2026,7,1),TablaIngresos[INCOME STATEMENT - REVENUE SECTION],"<"&DATE(2026,8,1)) | I40: =SUMIFS(TablaIngresos[Amount],TablaIngresos[Category],"Returns and allowances",TablaIngresos[INCOME STATEMENT - REVENUE SECTION],">="&DATE(2026,8,1),TablaIngresos[INCOME STATEMENT - REVENUE SECTION],"<"&DATE(2026,9,1)) | J40: =SUMIFS(TablaIngresos[Amount],TablaIngresos[Category],"Returns and allowances",TablaIngresos[INCOME STATEMENT - REVENUE SECTION],">="&DATE(2026,9,1),TablaIngresos[INCOME STATEMENT - REVENUE SECTION],"<"&DATE(2026,10,1)) | K40: =SUMIFS(TablaIngresos[Amount],TablaIngresos[Category],"Returns and allowances",TablaIngresos[INCOME STATEMENT - REVENUE SECTION],">="&DATE(2026,10,1),TablaIngresos[INCOME STATEMENT - REVENUE SECTION],"<"&DATE(2026,11,1)) | L40: =SUMIFS(TablaIngresos[Amount],TablaIngresos[Category],"Returns and allowances",TablaIngresos[INCOME STATEMENT - REVENUE SECTION],">="&DATE(2026,11,1),TablaIngresos[INCOME STATEMENT - REVENUE SECTION],"<"&DATE(2026,12,1)) | M40: =SUMIFS(TablaIngresos[Amount],TablaIngresos[Category],"Returns and allowances",TablaIngresos[INCOME STATEMENT - REVENUE SECTION],">="&DATE(2026,12,1),TablaIngresos[INCOME STATEMENT - REVENUE SECTION],"<"&DATE(2027,1,1)) | N40: =SUM(B40:M40)
A42: TOTAL EXPENSES | B42: =SUM(B14:B40) | C42: =SUM(C14:C40) | D42: =SUM(D14:D40) | E42: =SUM(E14:E40) | F42: =SUM(F14:F40) | G42: =SUM(G14:G40) | H42: =SUM(H14:H40) | I42: =SUM(I14:I40) | ... N42: =SUM(N14:N40)
A44: NET INCOME / UTILIDAD NETA | B44: =B11-B42 | C44: =C11-C42 | D44: =D11-D42 | E44: =E11-E42 | F44: =F11-F42 | G44: =G11-G42 | H44: =H11-H42 | I44: =I11-I42 | ... M44: =M11-M42 | N44: =SUM(B44:M44)

Sheet P&L Report
A1: PROFIT & LOSS STATEMENT
A2: January through December 2026
A5: REVENUE / INGRESOS
A6: Gross receipts or sales | B6: =SUMIF(TablaIngresos[Category],"Gross receipts or sales",TablaIngresos[Amount])
A7: Other income | B7: =SUMIF(TablaIngresos[Category],"Other income",TablaIngresos[Amount])
A8: Interest income | B8: =SUMIF(TablaIngresos[Category],"Interest income",TablaIngresos[Amount])
A9: Dividend income | B9: =SUMIF(TablaIngresos[Category],"Dividend income",TablaIngresos[Amount])
A10: Capital gains | B10: =SUMIF(TablaIngresos[Category],"Capital gains",TablaIngresos[Amount])
A11: Deposit | B11: =SUMIF(TablaIngresos[Category],"Deposit",TablaIngresos[Amount])
A12: TOTAL REVENUE | B12: =SUM(B6:B11)
A14: COST OF GOODS SOLD (COGS)
A15: Contract labor | B15: =SUMIF(Expenses!$E:$E,A15,Expenses!$I:$I)
A16: Cost of goods sold | B16: =SUMIF(Expenses!$E:$E,A16,Expenses!$I:$I)
A17: Supplies | B17: =SUMIF(Expenses!$E:$E,A17,Expenses!$I:$I)
A18: TOTAL COGS | B18: =SUM(B15:B17)
A20: OPERATING EXPENSES
A21: Advertising | B21: =SUMIF(Expenses!$E:$E,A21,Expenses!$I:$I)
A22: Car and truck expenses | B22: =SUMIF(Expenses!$E:$E,A22,Expenses!$I:$I)
A23: Commissions and fees | B23: =SUMIF(Expenses!$E:$E,A23,Expenses!$I:$I)
A24: Deductible meals | B24: =SUMIF(Expenses!$E:$E,A24,Expenses!$I:$I)
A25: Energy efficient commercial buildings deduction | B25: =SUMIF(Expenses!$E:$E,A25,Expenses!$I:$I)
A26: Insurance | B26: =SUMIF(Expenses!$E:$E,A26,Expenses!$I:$I)
A27: Legal and professional services | B27: =SUMIF(Expenses!$E:$E,A27,Expenses!$I:$I)
A28: Less returns and allowances | B28: =SUMIF(Expenses!$E:$E,A28,Expenses!$I:$I)
A29: Office expense | B29: =SUMIF(Expenses!$E:$E,A29,Expenses!$I:$I)
A30: Other business property | B30: =SUMIF(Expenses!$E:$E,A30,Expenses!$I:$I)
A31: Other deductions | B31: =SUMIF(Expenses!$E:$E,A31,Expenses!$I:$I)
A32: Other expenses | B32: =SUMIF(Expenses!$E:$E,A32,Expenses!$I:$I)
... A38: Vehicles, machinery, and equipment | B38: =SUMIF(Expenses!$E:$E,A38,Expenses!$I:$I)
A39: TOTAL OPERATING | B39: =SUM(B21:B38)
A41: PAYROLL EXPENSES
A42: Compensation of officers | B42: =SUMIF(Expenses!$E:$E,A42,Expenses!$I:$I)
A43: Employee benefit programs | B43: =SUMIF(Expenses!$E:$E,A43,Expenses!$I:$I)
A44: Pension, profit-sharing, etc., plans | B44: =SUMIF(Expenses!$E:$E,A44,Expenses!$I:$I)
A45: Salaries and wages (less employment credits) | B45: =SUMIF(Expenses!$E:$E,A45,Expenses!$I:$I)
A46: Wages | B46: =SUMIF(Expenses!$E:$E,A46,Expenses!$I:$I)
A47: TOTAL PAYROLL | B47: =SUM(B42:B46)
A49: FINANCIAL EXPENSES
A50: Bad debts | B50: =SUMIF(Expenses!$E:$E,A50,Expenses!$I:$I)
A51: Depletion (do not deduct oil and gas depletion) | B51: =SUMIF(Expenses!$E:$E,A51,Expenses!$I:$I)
...

Sheet Dashboard
A1: DASHBOARD - ANÁLISIS DE INGRESOS Y GASTOS
A2: Fiscal Year 2026
A5: INGRESOS POR CATEGORÍA | D5: INGRESOS (Solo con datos) | G5: Gráfico Ingresos
A6: Categoría | B6: Monto | D6: Categoría | E6: Monto | G6: Categoría | H6: Monto
A7: Gross receipts or sales | B7: =SUMIF(TablaIngresos[Category],"Gross receipts or sales",TablaIngresos[Amount]) | D7: =IF(B7>0, A7, "") | E7: =IF(B7>0, B7, "") | G7: {=_xlfn._xlws.FILTER(A7:A12, B7:B12>0, "Sin datos")} | H7: {=_xlfn._xlws.FILTER(B7:B12, B7:B12>0, 0)}
A8: Returns and allowances | B8: =SUMIF(TablaIngresos[Category],"Returns and allowances",TablaIngresos[Amount]) | D8: =IF(B8>0, A8, "") | E8: =IF(B8>0, B8, "")
A9: Other income | B9: =SUMIF(TablaIngresos[Category],"Other income",TablaIngresos[Amount]) | D9: =IF(B9>0, A9, "") | E9: =IF(B9>0, B9, "")
A10: Interest income | B10: =SUMIF(TablaIngresos[Category],"Interest income",TablaIngresos[Amount]) | D10: =IF(B10>0, A10, "") | E10: =IF(B10>0, B10, "")
A11: Dividend income | B11: =SUMIF(TablaIngresos[Category],"Dividend income",TablaIngresos[Amount]) | D11: =IF(B11>0, A11, "") | E11: =IF(B11>0, B11, "")
A12: Capital gains | B12: =SUMIF(TablaIngresos[Category],"Capital gains",TablaIngresos[Amount]) | D12: =IF(B12>0, A12, "") | E12: =IF(B12>0, B12, "")
A13: TOTAL | B13: =SUM(B7:B12)
G14: Gráfico Gastos
D15: GASTOS (Solo con datos) | G15: Categoría | H15: Monto
A16: GASTOS POR CATEGORÍA | D16: Categoría | E16: Monto | G16: {=_xlfn._xlws.FILTER(A18:A43, B18:B43>0, "Sin datos")} | H16: {=_xlfn._xlws.FILTER(B18:B43, B18:B43>0, 0)}
A17: Categoría | B17: Monto | D17: =IF(B18>0, A18, "") | E17: =IF(B18>0, B18, "")
A18: Advertising | B18: =SUMIF(TablaGastos[Category],"Advertising",TablaGastos[Amount]) | D18: =IF(B19>0, A19, "") | E18: =IF(B19>0, B19, "")
A19: Bad debts | B19: =SUMIF(TablaGastos[Category],"Bad debts",TablaGastos[Amount]) | D19: =IF(B20>0, A20, "") | E19: =IF(B20>0, B20, "")
A20: Car and truck expenses | B20: =SUMIF(TablaGastos[Category],"Car and truck expenses",TablaGastos[Amount]) | D20: =IF(B21>0, A21, "") | E20: =IF(B21>0, B21, "")
A21: Commissions and fees | B21: =SUMIF(TablaGastos[Category],"Commissions and fees",TablaGastos[Amount]) | D21: =IF(B22>0, A22, "") | E21: =IF(B22>0, B22, "")
A22: Compensation of officers | B22: =SUMIF(TablaGastos[Category],"Compensation of officers",TablaGastos[Amount]) | D22: =IF(B23>0, A23, "") | E22: =IF(B23>0, B23, "")
A23: Contract labor | B23: =SUMIF(TablaGastos[Category],"Contract labor",TablaGastos[Amount]) | D23: =IF(B24>0, A24, "") | E23: =IF(B24>0, B24, "")
A24: Cost of goods sold | B24: =SUMIF(TablaGastos[Category],"Cost of goods sold",TablaGastos[Amount]) | D24: =IF(B25>0, A25, "") | E24: =IF(B25>0, B25, "")
A25: Deductible meals | B25: =SUMIF(TablaGastos[Category],"Deductible meals",TablaGastos[Amount]) | D25: =IF(B26>0, A26, "") | E25: =IF(B26>0, B26, "")
A26: Depreciation | B26: =SUMIF(TablaGastos[Category],"Depreciation",TablaGastos[Amount]) | D26: =IF(B27>0, A27, "") | E26: =IF(B27>0, B27, "")
A27: Employee benefit programs | B27: =SUMIF(TablaGastos[Category],"Employee benefit programs",TablaGastos[Amount]) | D27: =IF(B28>0, A28, "") | E27: =IF(B28>0, B28, "")
A28: Insurance | B28: =SUMIF(TablaGastos[Category],"Insurance",TablaGastos[Amount]) | D28: =IF(B29>0, A29, "") | E28: =IF(B29>0, B29, "")
A29: Interest | B29: =SUMIF(TablaGastos[Category],"Interest",TablaGastos[Amount]) | D29: =IF(B30>0, A30, "") | E29: =IF(B30>0, B30, "")
A30: Legal and professional services | B30: =SUMIF(TablaGastos[Category],"Legal and professional services",TablaGastos[Amount]) | D30: =IF(B31>0, A31, "") | E30: =IF(B31>0, B31, "")
A31: Office expense | B31: =SUMIF(TablaGastos[Category],"Office expense",TablaGastos[Amount]) | D31: =IF(B32>0, A32, "") | E31: =IF(B32>0, B32, "")
A32: Other deductions | B32: =SUMIF(TablaGastos[Category],"Other deductions",TablaGastos[Amount]) | D32: =IF(B33>0, A33, "") | E32: =IF(B33>0, B33, "")
A33: Other expenses | B33: =SUMIF(TablaGastos[Category],"Other expenses",TablaGastos[Amount]) | D33: =IF(B34>0, A34, "") | E33: =IF(B34>0, B34, "")
A34: Pension, profit-sharing, etc., plans | B34: =SUMIF(TablaGastos[Category],"Pension, profit-sharing, etc., plans",TablaGastos[Amount]) | D34: =IF(B35>0, A35, "") | E34: =IF(B35>0, B35, "")
A35: Rent or lease | B35: =SUMIF(TablaGastos[Category],"Rent or lease",TablaGastos[Amount]) | D35: =IF(B36>0, A36, "") | E35: =IF(B36>0, B36, "")
A36: Repairs and maintenance | B36: =SUMIF(TablaGastos[Category],"Repairs and maintenance",TablaGastos[Amount]) | D36: =IF(B37>0, A37, "") | E36: =IF(B37>0, B37, "")
A37: Salaries and wages (less employment credits) | B37: =SUMIF(TablaGastos[Category],"Salaries and wages (less employment credits)",TablaGastos[Amount]) | D37: =IF(B38>0, A38, "") | E37: =IF(B38>0, B38, "")
A38: Suscription | B38: =SUMIF(TablaGastos[Category],"Suscriptions",TablaGastos[Amount]) | D38: =IF(B39>0, A39, "") | E38: =IF(B39>0, B39, "")
A39: Supplies | B39: =SUMIF(TablaGastos[Category],"Supplies",TablaGastos[Amount]) | D39: =IF(B40>0, A40, "") | E39: =IF(B40>0, B40, "")
A40: Taxes and licenses | B40: =SUMIF(TablaGastos[Category],"Taxes and licenses",TablaGastos[Amount]) | D40: =IF(B41>0, A41, "") | E40: =IF(B41>0, B41, "")
A41: Travel | B41: =SUMIF(TablaGastos[Category],"Travel",TablaGastos[Amount]) | D41: =IF(B42>0, A42, "") | E41: =IF(B42>0, B42, "")
A42: Utilities | B42: =SUMIF(TablaGastos[Category],"Utilities",TablaGastos[Amount]) | D42: =IF(B43>0, A43, "") | E42: =IF(B43>0, B43, "")
...

Sheet Settings
A1: Customers | C1: Suppliers | E1: Type | F1: Chart of Accounts | H1: Revenue Categories
C2: Office Depot | E2: Operating | F2: Advertising | H2: Gross receipts or sales
C3: Amazon | E3: Financial | F3: Bad debts | H3: Returns and allowances
C4: Amazon Prime | E4: Operating | F4: Car and truck expenses | H4: Other income
C5: Tmobile Auto pay | E5: Operating | F5: Commissions and fees | H5: Interest income
C6: Local owner | E6: Payroll | F6: Compensation of officers | H6: Dividend income
E7: COGS | F7: Contract labor | H7: Capital gains
E8: COGS | F8: Cost of goods sold | H8: Deposit
E9: Operating | F9: Deductible meals
E10: Taxes | F10: Deductions
E11: Financial | F11: Depletion (do not deduct oil and gas depletion)
E12: Financial | F12: Depreciation
E13: Payroll | F13: Employee benefit programs
E14: Operating | F14: Energy efficient commercial buildings deduction
E15: Operating | F15: Insurance
E16: Financial | F16: Interest
E17: Operating | F17: Legal and professional services
E18: Operating | F18: Less returns and allowances
E19: Financial | F19: Mortgage
E20: Operating | F20: Office expense
... E36: Non-Deductible | F36: Loan - Principal

Sheet Contract Labor
A1: CONTRACT LABOR PAYMENTS / PAGOS A CONTRATISTAS
A2: Fiscal Year 2026
A4: Date | B4: Document # | C4: Contractor Name | D4: Description | E4: Payment Method | F4: Amount | G4: Notes
A5: (Datos extraídos automáticamente de Expenses)
A7: {=IFERROR(_xlfn._xlws.FILTER(TablaGastos[Date],TablaGastos[Category]="Contract labor"),"")} | B7: {=IFERROR(_xlfn._xlws.FILTER(TablaGastos[Document Number],TablaGastos[Category]="Contract labor"),"")} | C7: {=IFERROR(_xlfn._xlws.FILTER(TablaGastos[Supplier],TablaGastos[Category]="Contract labor"),"")} | D7: {=IFERROR(_xlfn._xlws.FILTER(TablaGastos[Description],TablaGastos[Category]="Contract labor"),"")} | E7: {=IFERROR(_xlfn._xlws.FILTER(TablaGastos[Payment Method],TablaGastos[Category]="Contract labor"),"")} | F7: {=IFERROR(_xlfn._xlws.FILTER(TablaGastos[Amount],TablaGastos[Category]="Contract labor"),"")} | G7: {=IFERROR(_xlfn._xlws.FILTER(TablaGastos[Notes],TablaGastos[Category]="Contract labor"),"")}
A22: SUMMARY / RESUMEN
A24: Total Contract Labor (from Expenses): | C24: =SUMIF(TablaGastos[Category],"Contract labor",TablaGastos[Amount])
A27: GRAND TOTAL: | C27: =C24
A29: PAYMENTS BY CONTRACTOR / PAGOS POR CONTRATISTA
A31: Contractor Name | B31: Total Paid | C31: # Payments
A32: {=IFERROR(_xlfn._xlws.FILTER(_xlfn.UNIQUE(TablaGastos[Supplier]),COUNTIF(TablaGastos[Category],"Contract labor")>0),"No hay contratistas")} | B32: =IFERROR(SUMIFS(TablaGastos[Amount],TablaGastos[Category],"Contract labor",TablaGastos[Supplier],A32),"") | C32: =IFERROR(COUNTIFS(TablaGastos[Category],"Contract labor",TablaGastos[Supplier],A32),"")
A42: 📝 FUNCIONAMIENTO AUTOMÁTICO:
A43: 1. Los datos se extraen automáticamente de la hoja Expenses cuando la categoría es 'Contract labor'
A44: 2. La sección 'Payments by Contractor' muestra el resumen por cada contratista
A45: 3. Para agregar nuevos pagos, ve a la hoja Expenses y usa la categoría 'Contract labor'
A46: 4. Todo se actualiza automáticamente con fórmulas FILTER, UNIQUE y SUMIFS

Sheet Chart of Accounts
A1: Account # | B1: Account Name | C1: Account Type | D1: Sub-Type | E1: Description | F1: Balance
A2: 1000 | B2: Cash | C2: Asset | D2: Current Asset | E2: Efectivo en caja y bancos
A3: 1010 | B3: Checking Account | C3: Asset | D3: Current Asset | E3: Cuenta corriente
A4: 1020 | B4: Savings Account | C4: Asset | D4: Current Asset | E4: Cuenta de ahorros
A5: 1100 | B5: Accounts Receivable | C5: Asset | D5: Current Asset | E5: Cuentas por cobrar
A6: 1200 | B6: Inventory | C6: Asset | D6: Current Asset | E6: Inventario
A7: 1500 | B7: Equipment | C7: Asset | D7: Fixed Asset | E7: Equipo
A8: 1510 | B8: Accumulated Depreciation | C8: Asset | D8: Fixed Asset | E8: Depreciación acumulada
A9: 2000 | B9: Accounts Payable | C9: Liability | D9: Current Liability | E9: Cuentas por pagar
A10: 2100 | B10: Short-term Debt | C10: Liability | D10: Current Liability | E10: Deuda a corto plazo
A11: 2500 | B11: Long-term Debt | C11: Liability | D11: Long-term Liability | E11: Deuda a largo plazo
A12: 3000 | B12: Owner's Capital | C12: Equity | D12: Owner's Equity | E12: Capital del propietario
A13: 3100 | B13: Retained Earnings | C13: Equity | D13: Owner's Equity | E13: Ganancias retenidas
... A24: 5700 | B24: Interest Expense | C24: Expense | D24: Financing Expense | E24: Gasto de intereses

Sheet Journal Entry
A1: Entry # | B1: Date | C1: Description | D1: Account # | E1: Account Name | F1: Debit | G1: Credit | H1: Reference | I1: Notes
A2: Instructions:

Sheet General Ledger
A1: Trans # | B1: Date | C1: Account # | D1: Account Name | E1: Description | F1: Debit | G1: Credit | H1: Balance | I1: Reference
A2: This is auto-populated from Journal Entry

Sheet Trial Balance
A1: Trial Balance
A2: Account # | B2: Account Name | C2: Debit | D2: Credit
A26: TOTALS

Sheet Customers
A1: Customer ID | B1: Name | C1: Email | D1: Phone | E1: Address | F1: City | G1: Balance Due | H1: Credit Limit | I1: Status

Sheet Vendors
A1: Vendor ID | B1: Name | C1: Email | D1: Phone | E1: Address | F1: City | G1: Balance Due | H1: Payment Terms | I1: Status
